Workbook

Sheet Notes
F1: HOW TO:
F2: Export SeasonGame sheet and copy/paste to "Import Sheet" tab starting at C1, and to Old tab starting at H1
F3: Copy C1 and beyond to SeasonGame tab
F4: Put HomeTeam and AwayTeam (actual team names) in columns D and K in SeasonGame tab
F5: Save SeasonGame tab as SeasonGame in proper folder
F6: Delete out any non regular season game from newly created SeasonGame doc
F7: Before running code, switch out number of games per week (follow existing schedule, use countif to get numbers), Super Bowl Champion, divisonal games
F8: Run code and select which schedule you want
F9: Export selected schedule and week 18 games to New tab starting at C1
F10: On new, For the week 18 games, put NewSeasonWeek as 17
F11: On new, filter NewSeasonWeek from smallest to largest
F12: On new, move prime time, 1st game, and Thanksgiving games (NewSeasonWeek 11) around (in order of when played Sun-Thurs) (Thurs will be listed lastly I guess?) | G12: Looks like Sun - Thurs on 25 at least for Season 1
F13: On new, paste concat values from Game order tab for only regular season games (from 0-0 to 17-15, must be in order)
F14: On old, copy columns A and B and paste as values to PASTE IN tab
F15: Save PASTE IN tab as separate sheet and import back in to franchise editor
F16: Could probably also change the Name column values in Scheduler.Appointement to be safe

Sheet Import Sheet
A1: HomeTeam | B1: AwayTeam | C1: AwayPlayerStatCache | D1: Stadium | E1: ScoringSummaries | F1: AwayTeam | G1: AwayTeamStatCache | H1: GameGoal | I1: GameSetup | J1: HomePlayerStatCache | K1: InjuryCache | L1: HomeTeamStatCache | M1: HomeTeam | N1: AwayRequestId | O1: GameSessionId | P1: HomeRequestId | Q1: InitialMomentum | R1: GameStatus | S1: AwayScore | T1: NumberTimesPlayed | U1: TimeOfDay | V1: HomeTeamStatus | W1: AwayScoreQuarter1 | X1: AwayScoreOT | Y1: HomeScore | Z1: Temperature | AA1: LiveSeasonGameType | AB1: HomeScoreOT | AC1: AwayScoreQuarter4 | AD1: AwayScoreQuarter3 | AE1: AwayScoreQuarter2 | AF1: DayOfWeek | AG1: HomeScoreQuarter4 | AH1: HomeScoreQuarter3 | AI1: HomeScoreQuarter2 | AJ1: HomeScoreQuarter1 | AK1: IsGameOfTheWeek | AL1: CloudCover | AM1: Weather | AN1: SeasonWeekType | AO1: QuarterLengthMins | AP1: SeasonWeek | AQ1: SeasonGameNum | AR1: SeasonYear | AS1: ThanksgivingFlag | AT1: ChristmasFlag | AU1: NewYearsFlag | AV1: IsSimmed | AW1: HasBeenPublished | AX1: IsPractice | AY1: IsOvertimeGame | AZ1: PlayMomentType | BA1: AwayTeamStatus | BB1: ForceWin | BC1: Wind | BD1: Precipitation
A2: {=_xlfn.XLOOKUP(RIGHT(M2,8),TeamIdentity!C:C,TeamIdentity!A:A,NONE)} -> Bears | B2: {=_xlfn.XLOOKUP(RIGHT(F2,8),TeamIdentity!C:C,TeamIdentity!A:A,NONE)} -> Raiders | C2: 00000000000000000000000000000000 | D2: 00000000000000000000000000000000 | E2: 00000000000000000000000000000000 | F2: 00101101010010100000000000011100 | G2: 00000000000000000000000000000000 | H2: 00000000000000000000000000000000 | I2: 00000000000000000000000000000000 | J2: 00000000000000000000000000000000 | K2: 00000000000000000000000000000000 | L2: 00000000000000000000000000000000 | M2: 00101101010010100000000000000001 | N2: 90329 | O2: 0 | P2: 90328 | Q2: 0 | R2: Unplayed | S2: 0 | T2: 0 | U2: 1260 | V2: Pending | W2: 0 | X2: 0 | Y2: 0 | Z2: 0 | AA2: Regular | AB2: 0 | AC2: 0 | AD2: 0 | AE2: 0 | AF2: Monday | AG2: 0 | AH2: 0 | AI2: 0 | AJ2: 0 | AK2: FALSE | AL2: Invalid_ | AM2: Invalid_ | AN2: PreSeason | AO2: 14 | AP2: 0 | AQ2: 1 | AR2: 11 | AS2: FALSE | AT2: FALSE | AU2: FALSE | AV2: FALSE | AW2: FALSE | AX2: FALSE | AY2: FALSE | AZ2: IsDefenseOnly | BA2: Pending | BB2: None | BC2: Invalid_ | BD2: Invalid_
A3: {=_xlfn.XLOOKUP(RIGHT(M3,8),TeamIdentity!C:C,TeamIdentity!A:A,NONE)} -> Cowboys | B3: {=_xlfn.XLOOKUP(RIGHT(F3,8),TeamIdentity!C:C,TeamIdentity!A:A,NONE)} -> Bills | C3: 00000000000000000000000000000000 | D3: 00000000000000000000000000000000 | E3: 00000000000000000000000000000000 | F3: 00101101010010100000000000000011 | G3: 00000000000000000000000000000000 | H3: 00000000000000000000000000000000 | I3: 00000000000000000000000000000000 | J3: 00000000000000000000000000000000 | K3: 00000000000000000000000000000000 | L3: 00000000000000000000000000000000 | M3: 00101101010010100000000000001110 | N3: 90319 | O3: 0 | P3: 90318 | Q3: 0 | R3: Unplayed | S3: 0 | T3: 0 | U3: 1200 | V3: Pending | W3: 0 | X3: 0 | Y3: 0 | Z3: 0 | AA3: Regular | AB3: 0 | AC3: 0 | AD3: 0 | AE3: 0 | AF3: Saturday | AG3: 0 | AH3: 0 | AI3: 0 | AJ3: 0 | AK3: FALSE | AL3: Invalid_ | AM3: Invalid_ | AN3: PreSeason | AO3: 14 | AP3: 0 | AQ3: 10 | AR3: 11 | AS3: FALSE | AT3: FALSE | AU3: FALSE | AV3: FALSE | AW3: FALSE | AX3: FALSE | AY3: FALSE | AZ3: IsDefenseOnly | BA3: Pending | BB3: None | BC3: Invalid_ | BD3: Invalid_
A4: {=_xlfn.XLOOKUP(RIGHT(M4,8),TeamIdentity!C:C,TeamIdentity!A:A,NONE)} -> Seahawks | B4: {=_xlfn.XLOOKUP(RIGHT(F4,8),TeamIdentity!C:C,TeamIdentity!A:A,NONE)} -> Bengals | C4: 00000000000000000000000000000000 | D4: 00000000000000000000000000000000 | E4: 00000000000000000000000000000000 | F4: 00101101010010100000000000000010 | G4: 00000000000000000000000000000000 | H4: 00000000000000000000000000000000 | I4: 00000000000000000000000000000000 | J4: 00000000000000000000000000000000 | K4: 00000000000000000000000000000000 | L4: 00000000000000000000000000000000 | M4: 00101101010010100000000000100000 | N4: 90325 | O4: 0 | P4: 90324 | Q4: 0 | R4: Unplayed | S4: 0 | T4: 0 | U4: 1380 | V4: Pending | W4: 0 | X4: 0 | Y4: 0 | Z4: 0 | AA4: Regular | AB4: 0 | AC4: 0 | AD4: 0 | AE4: 0 | AF4: Saturday | AG4: 0 | AH4: 0 | AI4: 0 | AJ4: 0 | AK4: FALSE | AL4: Invalid_ | AM4: Invalid_ | AN4: PreSeason | AO4: 14 | AP4: 0 | AQ4: 15 | AR4: 11 | AS4: FALSE | AT4: FALSE | AU4: FALSE | AV4: FALSE | AW4: FALSE | AX4: FALSE | AY4: FALSE | AZ4: IsDefenseOnly | BA4: Pending | BB4: None | BC4: Invalid_ | BD4: Invalid_
A5: {=_xlfn.XLOOKUP(RIGHT(M5,8),TeamIdentity!C:C,TeamIdentity!A:A,NONE)} -> Falcons | B5: {=_xlfn.XLOOKUP(RIGHT(F5,8),TeamIdentity!C:C,TeamIdentity!A:A,NONE)} -> Browns | C5: 00000000000000000000000000000000 | D5: 00000000000000000000000000000000 | E5: 00000000000000000000000000000000 | F5: 00101101010010100000000000000101 | G5: 00000000000000000000000000000000 | H5: 00000000000000000000000000000000 | I5: 00000000000000000000000000000000 | J5: 00000000000000000000000000000000 | K5: 00000000000000000000000000000000 | L5: 00000000000000000000000000000000 | M5: 00101101010010100000000000010001 | N5: 90301 | O5: 0 | P5: 90300 | Q5: 0 | R5: Unplayed | S5: 0 | T5: 0 | U5: 1140 | V5: Pending | W5: 0 | X5: 0 | Y5: 0 | Z5: 0 | AA5: Regular | AB5: 0 | AC5: 0 | AD5: 0 | AE5: 0 | AF5: Friday | AG5: 0 | AH5: 0 | AI5: 0 | AJ5: 0 | AK5: FALSE | AL5: Invalid_ | AM5: Invalid_ | AN5: PreSeason | AO5: 14 | AP5: 0 | AQ5: 2 | AR5: 11 | AS5: FALSE | AT5: FALSE | AU5: FALSE | AV5: FALSE | AW5: FALSE | AX5: FALSE | AY5: FALSE | AZ5: IsDefenseOnly | BA5: Pending | BB5: None | BC5: Invalid_ | BD5: Invalid_
A6: {=_xlfn.XLOOKUP(RIGHT(M6,8),TeamIdentity!C:C,TeamIdentity!A:A,NONE)} -> Panthers | B6: {=_xlfn.XLOOKUP(RIGHT(F6,8),TeamIdentity!C:C,TeamIdentity!A:A,NONE)} -> Jets | C6: 00000000000000000000000000000000 | D6: 00000000000000000000000000000000 | E6: 00000000000000000000000000000000 | F6: 00101101010010100000000000010110 | G6: 00000000000000000000000000000000 | H6: 00000000000000000000000000000000 | I6: 00000000000000000000000000000000 | J6: 00000000000000000000000000000000 | K6: 00000000000000000000000000000000 | L6: 00000000000000000000000000000000 | M6: 00101101010010100000000000011010 | N6: 90315 | O6: 0 | P6: 90314 | Q6: 0 | R6: Unplayed | S6: 0 | T6: 0 | U6: 1200 | V6: Pending | W6: 0 | X6: 0 | Y6: 0 | Z6: 0 | AA6: Regular | AB6: 0 | AC6: 0 | AD6: 0 | AE6: 0 | AF6: Saturday | AG6: 0 | AH6: 0 | AI6: 0 | AJ6: 0 | AK6: FALSE | AL6: Invalid_ | AM6: Invalid_ | AN6: PreSeason | AO6: 14 | AP6: 0 | AQ6: 11 | AR6: 11 | AS6: FALSE | AT6: FALSE | AU6: FALSE | AV6: FALSE | AW6: FALSE | AX6: FALSE | AY6: FALSE | AZ6: IsDefenseOnly | BA6: Pending | BB6: None | BC6: Invalid_ | BD6: Invalid_
A7: {=_xlfn.XLOOKUP(RIGHT(M7,8),TeamIdentity!C:C,TeamIdentity!A:A,NONE)} -> Jaguars | B7: {=_xlfn.XLOOKUP(RIGHT(F7,8),TeamIdentity!C:C,TeamIdentity!A:A,NONE)} -> Commanders | C7: 00000000000000000000000000000000 | D7: 00000000000000000000000000000000 | E7: 00000000000000000000000000000000 | F7: 00101101010010100000000000001101 | G7: 00000000000000000000000000000000 | H7: 00000000000000000000000000000000 | I7: 00000000000000000000000000000000 | J7: 00000000000000000000000000000000 | K7: 00000000000000000000000000000000 | L7: 00000000000000000000000000000000 | M7: 00101101010010100000000000010101 | N7: 90317 | O7: 0 | P7: 90316 | Q7: 0 | R7: Unplayed | S7: 0 | T7: 0 | U7: 1200 | V7: Pending | W7: 0 | X7: 0 | Y7: 0 | Z7: 0 | AA7: Regular | AB7: 0 | AC7: 0 | AD7: 0 | AE7: 0 | AF7: Saturday | AG7: 0 | AH7: 0 | AI7: 0 | AJ7: 0 | AK7: FALSE | AL7: Invalid_ | AM7: Invalid_ | AN7: PreSeason | AO7: 14 | AP7: 0 | AQ7: 12 | AR7: 11 | AS7: FALSE | AT7: FALSE | AU7: FALSE | AV7: FALSE | AW7: FALSE | AX7: FALSE | AY7: FALSE | AZ7: IsDefenseOnly | BA7: Pending | BB7: None | BC7: Invalid_ | BD7: Invalid_
A8: {=_xlfn.XLOOKUP(RIGHT(M8,8),TeamIdentity!C:C,TeamIdentity!A:A,NONE)} -> Dolphins | B8: {=_xlfn.XLOOKUP(RIGHT(F8,8),TeamIdentity!C:C,TeamIdentity!A:A,NONE)} -> 49ers | C8: 00000000000000000000000000000000 | D8: 00000000000000000000000000000000 | E8: 00000000000000000000000000000000 | F8: 00101101010010100000000000000000 | G8: 00000000000000000000000000000000 | H8: 00000000000000000000000000000000 | I8: 00000000000000000000000000000000 | J8: 00000000000000000000000000000000 | K8: 00000000000000000000000000000000 | L8: 00000000000000000000000000000000 | M8: 00101101010010100000000000001111 | N8: 90299 | O8: 0 | P8: 90298 | Q8: 0 | R8: Unplayed | S8: 0 | T8: 0 | U8: 1140 | V8: Pending | W8: 0 | X8: 0 | Y8: 0 | Z8: 0 | AA8: Regular | AB8: 0 | AC8: 0 | AD8: 0 | AE8: 0 | AF8: Friday | AG8: 0 | AH8: 0 | AI8: 0 | AJ8: 0 | AK8: FALSE | AL8: Invalid_ | AM8: Invalid_ | AN8: PreSeason | AO8: 14 | AP8: 0 | AQ8: 3 | AR8: 11 | AS8: FALSE | AT8: FALSE | AU8: FALSE | AV8: FALSE | AW8: FALSE | AX8: FALSE | AY8: FALSE | AZ8: IsDefenseOnly | BA8: Pending | BB8: None | BC8: Invalid_ | BD8: Invalid_
A9: {=_xlfn.XLOOKUP(RIGHT(M9,8),TeamIdentity!C:C,TeamIdentity!A:A,NONE)} -> Lions | B9: {=_xlfn.XLOOKUP(RIGHT(F9,8),TeamIdentity!C:C,TeamIdentity!A:A,NONE)} -> Jaguars | C9: 00000000000000000000000000000000 | D9: 00000000000000000000000000000000 | E9: 00000000000000000000000000000000 | F9: 00101101010010100000000000010101 | G9: 00000000000000000000000000000000 | H9: 00000000000000000000000000000000 | I9: 00000000000000000000000000000000 | J9: 00000000000000000000000000000000 | K9: 00000000000000000000000000000000 | L9: 00000000000000000000000000000000 | M9: 00101101010010100000000000010111 | N9: -1 | O9: 0 | P9: -1 | Q9: 0 | R9: Unplayed | S9: 0 | T9: 0 | U9: 1200 | V9: Pending | W9: 0 | X9: 0 | Y9: 0 | Z9: 0 | AA9: Regular | AB9: 0 | AC9: 0 | AD9: 0 | AE9: 0 | AF9: Friday | AG9: 0 | AH9: 0 | AI9: 0 | AJ9: 0 | AK9: FALSE | AL9: Invalid_ | AM9: Invalid_ | AN9: PreSeason | AO9: 14 | AP9: 1 | AQ9: 9 | AR9: 11 | AS9: FALSE | AT9: FALSE | AU9: FALSE | AV9: FALSE | AW9: FALSE | AX9: FALSE | AY9: FALSE | AZ9: IsDefenseOnly | BA9: Pending | BB9: None | BC9: Invalid_ | BD9: Invalid_
A10: {=_xlfn.XLOOKUP(RIGHT(M10,8),TeamIdentity!C:C,TeamIdentity!A:A,NONE)} -> Eagles | B10: {=_xlfn.XLOOKUP(RIGHT(F10,8),TeamIdentity!C:C,TeamIdentity!A:A,NONE)} -> Ravens | C10: 00000000000000000000000000000000 | D10: 00000000000000000000000000000000 | E10: 00000000000000000000000000000000 | F10: 00101101010010100000000000011110 | G10: 00000000000000000000000000000000 | H10: 00000000000000000000000000000000 | I10: 00000000000000000000000000000000 | J10: 00000000000000000000000000000000 | K10: 00000000000000000000000000000000 | L10: 00000000000000000000000000000000 | M10: 00101101010010100000000000010000 | N10: 90309 | O10: 0 | P10: 90308 | Q10: 0 | R10: Unplayed | S10: 0 | T10: 0 | U10: 1140 | V10: Pending | W10: 0 | X10: 0 | Y10: 0 | Z10: 0 | AA10: Regular | AB10: 0 | AC10: 0 | AD10: 0 | AE10: 0 | AF10: Saturday | AG10: 0 | AH10: 0 | AI10: 0 | AJ10: 0 | AK10: FALSE | AL10: Invalid_ | AM10: Invalid_ | AN10: PreSeason | AO10: 14 | AP10: 0 | AQ10: 7 | AR10: 11 | AS10: FALSE | AT10: FALSE | AU10: FALSE | AV10: FALSE | AW10: FALSE | AX10: FALSE | AY10: FALSE | AZ10: IsDefenseOnly | BA10: Pending | BB10: None | BC10: Invalid_ | BD10: Invalid_
A11: {=_xlfn.XLOOKUP(RIGHT(M11,8),TeamIdentity!C:C,TeamIdentity!A:A,NONE)} -> Cardinals | B11: {=_xlfn.XLOOKUP(RIGHT(F11,8),TeamIdentity!C:C,TeamIdentity!A:A,NONE)} -> Colts | C11: 00000000000000000000000000000000 | D11: 00000000000000000000000000000000 | E11: 00000000000000000000000000000000 | F11: 00101101010010100000000000001100 | G11: 00000000000000000000000000000000 | H11: 00000000000000000000000000000000 | I11: 00000000000000000000000000000000 | J11: 00000000000000000000000000000000 | K11: 00000000000000000000000000000000 | L11: 00000000000000000000000000000000 | M11: 00101101010010100000000000000111 | N11: 90307 | O11: 0 | P11: 90306 | Q11: 0 | R11: Unplayed | S11: 0 | T11: 0 | U11: 1320 | V11: Pending | W11: 0 | X11: 0 | Y11: 0 | Z11: 0 | AA11: Regular | AB11: 0 | AC11: 0 | AD11: 0 | AE11: 0 | AF11: Friday | AG11: 0 | AH11: 0 | AI11: 0 | AJ11: 0 | AK11: FALSE | AL11: Invalid_ | AM11: Invalid_ | AN11: PreSeason | AO11: 14 | AP11: 0 | AQ11: 5 | AR11: 11 | AS11: FALSE | AT11: FALSE | AU11: FALSE | AV11: FALSE | AW11: FALSE | AX11: FALSE | AY11: FALSE | AZ11: IsDefenseOnly | BA11: Pending | BB11: None | BC11: Invalid_ | BD11: Invalid_
A12: {=_xlfn.XLOOKUP(RIGHT(M12,8),TeamIdentity!C:C,TeamIdentity!A:A,NONE)} -> Patriots | B12: {=_xlfn.XLOOKUP(RIGHT(F12,8),TeamIdentity!C:C,TeamIdentity!A:A,NONE)} -> Packers | C12: 00000000000000000000000000000000 | D12: 00000000000000000000000000000000 | E12: 00000000000000000000000000000000 | F12: 00101101010010100000000000011001 | G12: 00000000000000000000000000000000 | H12: 00000000000000000000000000000000 | I12: 00000000000000000000000000000000 | J12: 00000000000000000000000000000000 | K12: 00000000000000000000000000000000 | L12: 00000000000000000000000000000000 | M12: 00101101010010100000000000011011 | N12: 90303 | O12: 0 | P12: 90302 | Q12: 0 | R12: Unplayed | S12: 0 | T12: 0 | U12: 1200 | V12: Pending | W12: 0 | X12: 0 | Y12: 0 | Z12: 0 | AA12: Regular | AB12: 0 | AC12: 0 | AD12: 0 | AE12: 0 | AF12: Friday | AG12: 0 | AH12: 0 | AI12: 0 | AJ12: 0 | AK12: FALSE | AL12: Invalid_ | AM12: Invalid_ | AN12: PreSeason | AO12: 14 | AP12: 0 | AQ12: 4 | AR12: 11 | AS12: FALSE | AT12: FALSE | AU12: FALSE | AV12: FALSE | AW12: FALSE | AX12: FALSE | AY12: FALSE | AZ12: IsDefenseOnly | BA12: Pending | BB12: None | BC12: Invalid_ | BD12: Invalid_
A13: {=_xlfn.XLOOKUP(RIGHT(M13,8),TeamIdentity!C:C,TeamIdentity!A:A,NONE)} -> Steelers | B13: {=_xlfn.XLOOKUP(RIGHT(F13,8),TeamIdentity!C:C,TeamIdentity!A:A,NONE)} -> Giants | C13: 00000000000000000000000000000000 | D13: 00000000000000000000000000000000 | E13: 00000000000000000000000000000000 | F13: 00101101010010100000000000010011 | G13: 00000000000000000000000000000000 | H13: 00000000000000000000000000000000 | I13: 00000000000000000000000000000000 | J13: 00000000000000000000000000000000 | K13: 00000000000000000000000000000000 | L13: 00000000000000000000000000000000 | M13: 00101101010010100000000000100001 | N13: 90311 | O13: 0 | P13: 90310 | Q13: 0 | R13: Unplayed | S13: 0 | T13: 0 | U13: 1140 | V13: Pending | W13: 0 | X13: 0 | Y13: 0 | Z13: 0 | AA13: Regular | AB13: 0 | AC13: 0 | AD13: 0 | AE13: 0 | AF13: Saturday | AG13: 0 | AH13: 0 | AI13: 0 | AJ13: 0 | AK13: FALSE | AL13: Invalid_ | AM13: Invalid_ | AN13: PreSeason | AO13: 14 | AP13: 0 | AQ13: 8 | AR13: 11 | AS13: FALSE | AT13: FALSE | AU13: FALSE | AV13: FALSE | AW13: FALSE | AX13: FALSE | AY13: FALSE | AZ13: IsDefenseOnly | BA13: Pending | BB13: None | BC13: Invalid_ | BD13: Invalid_
... A430: {=_xlfn.XLOOKUP(RIGHT(M430,8),TeamIdentity!C:C,TeamIdentity!A:A,NONE)} -> 49ers | B430: {=_xlfn.XLOOKUP(RIGHT(F430,8),TeamIdentity!C:C,TeamIdentity!A:A,NONE)} -> 49ers | C430: 00000000000000000000000110101101 | D430: 00000000000000000000000000000000 | E430: 00000000000000000000000000000000 | F430: 00000000000000000000000000000000 | G430: 00000000000000000000000000000000 | H430: 00000000000000000000000000000000 | I430: 00000000000000000000000000000000 | J430: 00000000000000000000000000000000 | K430: 00000000000000000000000000000000 | L430: 00000000000000000000000000000000 | M430: 00000000000000000000000000000000 | N430: -2147483648 | O430: -2147483648 | P430: -2147483648 | Q430: 0 | R430: Unscheduled | S430: 0 | T430: 0 | U430: 0 | V430: Pending | W430: 0 | X430: 0 | Y430: 0 | Z430: -100 | AA430: Regular | AB430: 0 | AC430: 0 | AD430: 0 | AE430: 0 | AF430: Sunday | AG430: 0 | AH430: 0 | AI430: 0 | AJ430: 0 | AK430: FALSE | AL430: None | AM430: Clear | AN430: PreSeason | AO430: 0 | AP430: 0 | AQ430: 0 | AR430: 0 | AS430: FALSE | AT430: FALSE | AU430: FALSE | AV430: FALSE | AW430: FALSE | AX430: FALSE | AY430: FALSE | AZ430: IsPlayTheMoment | BA430: Pending | BB430: Home | BC430: Calm | BD430: None

Sheet Save as SeasonGame
A1: AwayPlayerStatCache | B1: Stadium | C1: ScoringSummaries | D1: AwayTeam | E1: AwayTeamStatCache | F1: GameGoal | G1: GameSetup | H1: HomePlayerStatCache | I1: InjuryCache | J1: HomeTeamStatCache | K1: HomeTeam | L1: AwayRequestId | M1: GameSessionId | N1: HomeRequestId | O1: InitialMomentum | P1: GameStatus | Q1: AwayScore | R1: NumberTimesPlayed | S1: TimeOfDay | T1: HomeTeamStatus | U1: AwayScoreQuarter1 | V1: AwayScoreOT | W1: HomeScore | X1: Temperature | Y1: LiveSeasonGameType | Z1: HomeScoreOT | AA1: AwayScoreQuarter4 | AB1: AwayScoreQuarter3 | AC1: AwayScoreQuarter2 | AD1: DayOfWeek | AE1: HomeScoreQuarter4 | AF1: HomeScoreQuarter3 | AG1: HomeScoreQuarter2 | AH1: HomeScoreQuarter1 | AI1: IsGameOfTheWeek | AJ1: CloudCover | AK1: Weather | AL1: SeasonWeekType | AM1: QuarterLengthMins | AN1: SeasonWeek | AO1: SeasonGameNum | AP1: SeasonYear | AQ1: ThanksgivingFlag | AR1: ChristmasFlag | AS1: NewYearsFlag | AT1: IsSimmed | AU1: HasBeenPublished | AV1: IsPractice | AW1: IsOvertimeGame | AX1: PlayMomentType | AY1: AwayTeamStatus | AZ1: ForceWin | BA1: Wind | BB1: Precipitation
A2: 00000000000000000000000000000000 | B2: 00000000000000000000000000000000 | C2: 00000000000000000000000000000000 | D2: Raiders | E2: 00000000000000000000000000000000 | F2: 00000000000000000000000000000000 | G2: 00000000000000000000000000000000 | H2: 00000000000000000000000000000000 | I2: 00000000000000000000000000000000 | J2: 00000000000000000000000000000000 | K2: Bears | L2: 90329 | M2: 0 | N2: 90328 | O2: 0 | P2: Unplayed | Q2: 0 | R2: 0 | S2: 1260 | T2: Pending | U2: 0 | V2: 0 | W2: 0 | X2: 0 | Y2: Regular | Z2: 0 | AA2: 0 | AB2: 0 | AC2: 0 | AD2: Monday | AE2: 0 | AF2: 0 | AG2: 0 | AH2: 0 | AI2: FALSE | AJ2: Invalid_ | AK2: Invalid_ | AL2: PreSeason | AM2: 14 | AN2: 0 | AO2: 1 | AP2: 11 | AQ2: FALSE | AR2: FALSE | AS2: FALSE | AT2: FALSE | AU2: FALSE | AV2: FALSE | AW2: FALSE | AX2: IsDefenseOnly | AY2: Pending | AZ2: None | BA2: Invalid_ | BB2: Invalid_
A3: 00000000000000000000000000000000 | B3: 00000000000000000000000000000000 | C3: 00000000000000000000000000000000 | D3: Bills | E3: 00000000000000000000000000000000 | F3: 00000000000000000000000000000000 | G3: 00000000000000000000000000000000 | H3: 00000000000000000000000000000000 | I3: 00000000000000000000000000000000 | J3: 00000000000000000000000000000000 | K3: Cowboys | L3: 90319 | M3: 0 | N3: 90318 | O3: 0 | P3: Unplayed | Q3: 0 | R3: 0 | S3: 1200 | T3: Pending | U3: 0 | V3: 0 | W3: 0 | X3: 0 | Y3: Regular | Z3: 0 | AA3: 0 | AB3: 0 | AC3: 0 | AD3: Saturday | AE3: 0 | AF3: 0 | AG3: 0 | AH3: 0 | AI3: FALSE | AJ3: Invalid_ | AK3: Invalid_ | AL3: PreSeason | AM3: 14 | AN3: 0 | AO3: 10 | AP3: 11 | AQ3: FALSE | AR3: FALSE | AS3: FALSE | AT3: FALSE | AU3: FALSE | AV3: FALSE | AW3: FALSE | AX3: IsDefenseOnly | AY3: Pending | AZ3: None | BA3: Invalid_ | BB3: Invalid_
A4: 00000000000000000000000000000000 | B4: 00000000000000000000000000000000 | C4: 00000000000000000000000000000000 | D4: Bengals | E4: 00000000000000000000000000000000 | F4: 00000000000000000000000000000000 | G4: 00000000000000000000000000000000 | H4: 00000000000000000000000000000000 | I4: 00000000000000000000000000000000 | J4: 00000000000000000000000000000000 | K4: Seahawks | L4: 90325 | M4: 0 | N4: 90324 | O4: 0 | P4: Unplayed | Q4: 0 | R4: 0 | S4: 1380 | T4: Pending | U4: 0 | V4: 0 | W4: 0 | X4: 0 | Y4: Regular | Z4: 0 | AA4: 0 | AB4: 0 | AC4: 0 | AD4: Saturday | AE4: 0 | AF4: 0 | AG4: 0 | AH4: 0 | AI4: FALSE | AJ4: Invalid_ | AK4: Invalid_ | AL4: PreSeason | AM4: 14 | AN4: 0 | AO4: 15 | AP4: 11 | AQ4: FALSE | AR4: FALSE | AS4: FALSE | AT4: FALSE | AU4: FALSE | AV4: FALSE | AW4: FALSE | AX4: IsDefenseOnly | AY4: Pending | AZ4: None | BA4: Invalid_ | BB4: Invalid_
A5: 00000000000000000000000000000000 | B5: 00000000000000000000000000000000 | C5: 00000000000000000000000000000000 | D5: Browns | E5: 00000000000000000000000000000000 | F5: 00000000000000000000000000000000 | G5: 00000000000000000000000000000000 | H5: 00000000000000000000000000000000 | I5: 00000000000000000000000000000000 | J5: 00000000000000000000000000000000 | K5: Falcons | L5: 90301 | M5: 0 | N5: 90300 | O5: 0 | P5: Unplayed | Q5: 0 | R5: 0 | S5: 1140 | T5: Pending | U5: 0 | V5: 0 | W5: 0 | X5: 0 | Y5: Regular | Z5: 0 | AA5: 0 | AB5: 0 | AC5: 0 | AD5: Friday | AE5: 0 | AF5: 0 | AG5: 0 | AH5: 0 | AI5: FALSE | AJ5: Invalid_ | AK5: Invalid_ | AL5: PreSeason | AM5: 14 | AN5: 0 | AO5: 2 | AP5: 11 | AQ5: FALSE | AR5: FALSE | AS5: FALSE | AT5: FALSE | AU5: FALSE | AV5: FALSE | AW5: FALSE | AX5: IsDefenseOnly | AY5: Pending | AZ5: None | BA5: Invalid_ | BB5: Invalid_
A6: 00000000000000000000000000000000 | B6: 00000000000000000000000000000000 | C6: 00000000000000000000000000000000 | D6: Jets | E6: 00000000000000000000000000000000 | F6: 00000000000000000000000000000000 | G6: 00000000000000000000000000000000 | H6: 00000000000000000000000000000000 | I6: 00000000000000000000000000000000 | J6: 00000000000000000000000000000000 | K6: Panthers | L6: 90315 | M6: 0 | N6: 90314 | O6: 0 | P6: Unplayed | Q6: 0 | R6: 0 | S6: 1200 | T6: Pending | U6: 0 | V6: 0 | W6: 0 | X6: 0 | Y6: Regular | Z6: 0 | AA6: 0 | AB6: 0 | AC6: 0 | AD6: Saturday | AE6: 0 | AF6: 0 | AG6: 0 | AH6: 0 | AI6: FALSE | AJ6: Invalid_ | AK6: Invalid_ | AL6: PreSeason | AM6: 14 | AN6: 0 | AO6: 11 | AP6: 11 | AQ6: FALSE | AR6: FALSE | AS6: FALSE | AT6: FALSE | AU6: FALSE | AV6: FALSE | AW6: FALSE | AX6: IsDefenseOnly | AY6: Pending | AZ6: None | BA6: Invalid_ | BB6: Invalid_
A7: 00000000000000000000000000000000 | B7: 00000000000000000000000000000000 | C7: 00000000000000000000000000000000 | D7: Commanders | E7: 00000000000000000000000000000000 | F7: 00000000000000000000000000000000 | G7: 00000000000000000000000000000000 | H7: 00000000000000000000000000000000 | I7: 00000000000000000000000000000000 | J7: 00000000000000000000000000000000 | K7: Jaguars | L7: 90317 | M7: 0 | N7: 90316 | O7: 0 | P7: Unplayed | Q7: 0 | R7: 0 | S7: 1200 | T7: Pending | U7: 0 | V7: 0 | W7: 0 | X7: 0 | Y7: Regular | Z7: 0 | AA7: 0 | AB7: 0 | AC7: 0 | AD7: Saturday | AE7: 0 | AF7: 0 | AG7: 0 | AH7: 0 | AI7: FALSE | AJ7: Invalid_ | AK7: Invalid_ | AL7: PreSeason | AM7: 14 | AN7: 0 | AO7: 12 | AP7: 11 | AQ7: FALSE | AR7: FALSE | AS7: FALSE | AT7: FALSE | AU7: FALSE | AV7: FALSE | AW7: FALSE | AX7: IsDefenseOnly | AY7: Pending | AZ7: None | BA7: Invalid_ | BB7: Invalid_
A8: 00000000000000000000000000000000 | B8: 00000000000000000000000000000000 | C8: 00000000000000000000000000000000 | D8: 49ers | E8: 00000000000000000000000000000000 | F8: 00000000000000000000000000000000 | G8: 00000000000000000000000000000000 | H8: 00000000000000000000000000000000 | I8: 00000000000000000000000000000000 | J8: 00000000000000000000000000000000 | K8: Dolphins | L8: 90299 | M8: 0 | N8: 90298 | O8: 0 | P8: Unplayed | Q8: 0 | R8: 0 | S8: 1140 | T8: Pending | U8: 0 | V8: 0 | W8: 0 | X8: 0 | Y8: Regular | Z8: 0 | AA8: 0 | AB8: 0 | AC8: 0 | AD8: Friday | AE8: 0 | AF8: 0 | AG8: 0 | AH8: 0 | AI8: FALSE | AJ8: Invalid_ | AK8: Invalid_ | AL8: PreSeason | AM8: 14 | AN8: 0 | AO8: 3 | AP8: 11 | AQ8: FALSE | AR8: FALSE | AS8: FALSE | AT8: FALSE | AU8: FALSE | AV8: FALSE | AW8: FALSE | AX8: IsDefenseOnly | AY8: Pending | AZ8: None | BA8: Invalid_ | BB8: Invalid_
A9: 00000000000000000000000000000000 | B9: 00000000000000000000000000000000 | C9: 00000000000000000000000000000000 | D9: Jaguars | E9: 00000000000000000000000000000000 | F9: 00000000000000000000000000000000 | G9: 00000000000000000000000000000000 | H9: 00000000000000000000000000000000 | I9: 00000000000000000000000000000000 | J9: 00000000000000000000000000000000 | K9: Lions | L9: -1 | M9: 0 | N9: -1 | O9: 0 | P9: Unplayed | Q9: 0 | R9: 0 | S9: 1200 | T9: Pending | U9: 0 | V9: 0 | W9: 0 | X9: 0 | Y9: Regular | Z9: 0 | AA9: 0 | AB9: 0 | AC9: 0 | AD9: Friday | AE9: 0 | AF9: 0 | AG9: 0 | AH9: 0 | AI9: FALSE | AJ9: Invalid_ | AK9: Invalid_ | AL9: PreSeason | AM9: 14 | AN9: 1 | AO9: 9 | AP9: 11 | AQ9: FALSE | AR9: FALSE | AS9: FALSE | AT9: FALSE | AU9: FALSE | AV9: FALSE | AW9: FALSE | AX9: IsDefenseOnly | AY9: Pending | AZ9: None | BA9: Invalid_ | BB9: Invalid_
A10: 00000000000000000000000000000000 | B10: 00000000000000000000000000000000 | C10: 00000000000000000000000000000000 | D10: Ravens | E10: 00000000000000000000000000000000 | F10: 00000000000000000000000000000000 | G10: 00000000000000000000000000000000 | H10: 00000000000000000000000000000000 | I10: 00000000000000000000000000000000 | J10: 00000000000000000000000000000000 | K10: Eagles | L10: 90309 | M10: 0 | N10: 90308 | O10: 0 | P10: Unplayed | Q10: 0 | R10: 0 | S10: 1140 | T10: Pending | U10: 0 | V10: 0 | W10: 0 | X10: 0 | Y10: Regular | Z10: 0 | AA10: 0 | AB10: 0 | AC10: 0 | AD10: Saturday | AE10: 0 | AF10: 0 | AG10: 0 | AH10: 0 | AI10: FALSE | AJ10: Invalid_ | AK10: Invalid_ | AL10: PreSeason | AM10: 14 | AN10: 0 | AO10: 7 | AP10: 11 | AQ10: FALSE | AR10: FALSE | AS10: FALSE | AT10: FALSE | AU10: FALSE | AV10: FALSE | AW10: FALSE | AX10: IsDefenseOnly | AY10: Pending | AZ10: None | BA10: Invalid_ | BB10: Invalid_
A11: 00000000000000000000000000000000 | B11: 00000000000000000000000000000000 | C11: 00000000000000000000000000000000 | D11: Colts | E11: 00000000000000000000000000000000 | F11: 00000000000000000000000000000000 | G11: 00000000000000000000000000000000 | H11: 00000000000000000000000000000000 | I11: 00000000000000000000000000000000 | J11: 00000000000000000000000000000000 | K11: Cardinals | L11: 90307 | M11: 0 | N11: 90306 | O11: 0 | P11: Unplayed | Q11: 0 | R11: 0 | S11: 1320 | T11: Pending | U11: 0 | V11: 0 | W11: 0 | X11: 0 | Y11: Regular | Z11: 0 | AA11: 0 | AB11: 0 | AC11: 0 | AD11: Friday | AE11: 0 | AF11: 0 | AG11: 0 | AH11: 0 | AI11: FALSE | AJ11: Invalid_ | AK11: Invalid_ | AL11: PreSeason | AM11: 14 | AN11: 0 | AO11: 5 | AP11: 11 | AQ11: FALSE | AR11: FALSE | AS11: FALSE | AT11: FALSE | AU11: FALSE | AV11: FALSE | AW11: FALSE | AX11: IsDefenseOnly | AY11: Pending | AZ11: None | BA11: Invalid_ | BB11: Invalid_
A12: 00000000000000000000000000000000 | B12: 00000000000000000000000000000000 | C12: 00000000000000000000000000000000 | D12: Packers | E12: 00000000000000000000000000000000 | F12: 00000000000000000000000000000000 | G12: 00000000000000000000000000000000 | H12: 00000000000000000000000000000000 | I12: 00000000000000000000000000000000 | J12: 00000000000000000000000000000000 | K12: Patriots | L12: 90303 | M12: 0 | N12: 90302 | O12: 0 | P12: Unplayed | Q12: 0 | R12: 0 | S12: 1200 | T12: Pending | U12: 0 | V12: 0 | W12: 0 | X12: 0 | Y12: Regular | Z12: 0 | AA12: 0 | AB12: 0 | AC12: 0 | AD12: Friday | AE12: 0 | AF12: 0 | AG12: 0 | AH12: 0 | AI12: FALSE | AJ12: Invalid_ | AK12: Invalid_ | AL12: PreSeason | AM12: 14 | AN12: 0 | AO12: 4 | AP12: 11 | AQ12: FALSE | AR12: FALSE | AS12: FALSE | AT12: FALSE | AU12: FALSE | AV12: FALSE | AW12: FALSE | AX12: IsDefenseOnly | AY12: Pending | AZ12: None | BA12: Invalid_ | BB12: Invalid_
A13: 00000000000000000000000000000000 | B13: 00000000000000000000000000000000 | C13: 00000000000000000000000000000000 | D13: Giants | E13: 00000000000000000000000000000000 | F13: 00000000000000000000000000000000 | G13: 00000000000000000000000000000000 | H13: 00000000000000000000000000000000 | I13: 00000000000000000000000000000000 | J13: 00000000000000000000000000000000 | K13: Steelers | L13: 90311 | M13: 0 | N13: 90310 | O13: 0 | P13: Unplayed | Q13: 0 | R13: 0 | S13: 1140 | T13: Pending | U13: 0 | V13: 0 | W13: 0 | X13: 0 | Y13: Regular | Z13: 0 | AA13: 0 | AB13: 0 | AC13: 0 | AD13: Saturday | AE13: 0 | AF13: 0 | AG13: 0 | AH13: 0 | AI13: FALSE | AJ13: Invalid_ | AK13: Invalid_ | AL13: PreSeason | AM13: 14 | AN13: 0 | AO13: 8 | AP13: 11 | AQ13: FALSE | AR13: FALSE | AS13: FALSE | AT13: FALSE | AU13: FALSE | AV13: FALSE | AW13: FALSE | AX13: IsDefenseOnly | AY13: Pending | AZ13: None | BA13: Invalid_ | BB13: Invalid_
... A430: 00000000000000000000000110101101 | B430: 00000000000000000000000000000000 | C430: 00000000000000000000000000000000 | D430: 49ers | E430: 00000000000000000000000000000000 | F430: 00000000000000000000000000000000 | G430: 00000000000000000000000000000000 | H430: 00000000000000000000000000000000 | I430: 00000000000000000000000000000000 | J430: 00000000000000000000000000000000 | K430: 49ers | L430: -2147483648 | M430: -2147483648 | N430: -2147483648 | O430: 0 | P430: Unscheduled | Q430: 0 | R430: 0 | S430: 0 | T430: Pending | U430: 0 | V430: 0 | W430: 0 | X430: -100 | Y430: Regular | Z430: 0 | AA430: 0 | AB430: 0 | AC430: 0 | AD430: Sunday | AE430: 0 | AF430: 0 | AG430: 0 | AH430: 0 | AI430: FALSE | AJ430: None | AK430: Clear | AL430: PreSeason | AM430: 0 | AN430: 0 | AO430: 0 | AP430: 0 | AQ430: FALSE | AR430: FALSE | AS430: FALSE | AT430: FALSE | AU430: FALSE | AV430: FALSE | AW430: FALSE | AX430: IsPlayTheMoment | AY430: Pending | AZ430: Home | BA430: Calm | BB430: None

Sheet Old
A1: HomeTeam | B1: AwayTeam | C1: HomeTeam (with new schedule) | D1: AwayTeam (with new schedule) | E1: Home Name | F1: Away Name | G1: Concat | H1: AwayPlayerStatCache | I1: Stadium | J1: ScoringSummaries | K1: AwayTeam | L1: AwayTeamStatCache | M1: GameGoal | N1: GameSetup | O1: HomePlayerStatCache | P1: InjuryCache | Q1: HomeTeamStatCache | R1: HomeTeam | S1: AwayRequestId | T1: GameSessionId | U1: HomeRequestId | V1: InitialMomentum | W1: GameStatus | X1: AwayScore | Y1: NumberTimesPlayed | Z1: TimeOfDay | AA1: HomeTeamStatus | AB1: AwayScoreQuarter1 | AC1: AwayScoreOT | AD1: HomeScore | AE1: Temperature | AF1: LiveSeasonGameType | AG1: HomeScoreOT | AH1: AwayScoreQuarter4 | AI1: AwayScoreQuarter3 | AJ1: AwayScoreQuarter2 | AK1: DayOfWeek | AL1: HomeScoreQuarter4 | AM1: HomeScoreQuarter3 | AN1: HomeScoreQuarter2 | AO1: HomeScoreQuarter1 | AP1: IsGameOfTheWeek | AQ1: CloudCover | AR1: Weather | AS1: SeasonWeekType | AT1: QuarterLengthMins | AU1: SeasonWeek | AV1: SeasonGameNum | AW1: SeasonYear | AX1: ThanksgivingFlag | AY1: ChristmasFlag | AZ1: NewYearsFlag | BA1: IsSimmed | BB1: HasBeenPublished | BC1: IsPractice | BD1: IsOvertimeGame | BE1: PlayMomentType | BF1: AwayTeamStatus | BG1: ForceWin | BH1: Wind | BI1: Precipitation
A2: {=_xlfn.IFS(AS2="RegularSeason",C2,AS2<>"RegularSeason",R2)} -> 00101101010010100000000000000001 | B2: {=_xlfn.IFS(AS2="RegularSeason",D2,AS2<>"RegularSeason",K2)} -> 00101101010010100000000000011100 | C2: =_xlfn.CONCAT(LEFT(R2,24),E2) -> 00101101010010100000000000000111 | D2: =_xlfn.CONCAT(LEFT(K2,24),F2) -> 00101101010010100000000000001101 | E2: {=_xlfn.XLOOKUP(_xlfn.XLOOKUP(G2,New!A:A,New!M:M,NONE),TeamIdentity!A:A,TeamIdentity!C:C,NONE)} -> 00000111 | F2: {=_xlfn.XLOOKUP(_xlfn.XLOOKUP(G2,New!A:A,New!F:F,NONE),TeamIdentity!A:A,TeamIdentity!C:C,NONE)} -> 00001101 | G2: =_xlfn.CONCAT(AU2,"-",AV2) -> 0-1 | H2: 00000000000000000000000000000000 | I2: 00000000000000000000000000000000 | J2: 00000000000000000000000000000000 | K2: 00101101010010100000000000011100 | L2: 00000000000000000000000000000000 | M2: 00000000000000000000000000000000 | N2: 00000000000000000000000000000000 | O2: 00000000000000000000000000000000 | P2: 00000000000000000000000000000000 | Q2: 00000000000000000000000000000000 | R2: 00101101010010100000000000000001 | S2: 90329 | T2: 0 | U2: 90328 | V2: 0 | W2: Unplayed | X2: 0 | Y2: 0 | Z2: 1260 | AA2: Pending | AB2: 0 | AC2: 0 | AD2: 0 | AE2: 0 | AF2: Regular | AG2: 0 | AH2: 0 | AI2: 0 | AJ2: 0 | AK2: Monday | AL2: 0 | AM2: 0 | AN2: 0 | AO2: 0 | AP2: FALSE | AQ2: Invalid_ | AR2: Invalid_ | AS2: PreSeason | AT2: 14 | AU2: 0 | AV2: 1 | AW2: 11 | AX2: FALSE | AY2: FALSE | AZ2: FALSE | BA2: FALSE | BB2: FALSE | BC2: FALSE | BD2: FALSE | BE2: IsDefenseOnly | BF2: Pending | BG2: None | BH2: Invalid_ | BI2: Invalid_
A3: {=_xlfn.IFS(AS3="RegularSeason",C3,AS3<>"RegularSeason",R3)} -> 00101101010010100000000000001110 | B3: {=_xlfn.IFS(AS3="RegularSeason",D3,AS3<>"RegularSeason",K3)} -> 00101101010010100000000000000011 | C3: =_xlfn.CONCAT(LEFT(R3,24),E3) -> 00101101010010100000000000010001 | D3: =_xlfn.CONCAT(LEFT(K3,24),F3) -> 00101101010010100000000000001100 | E3: {=_xlfn.XLOOKUP(_xlfn.XLOOKUP(G3,New!A:A,New!M:M,NONE),TeamIdentity!A:A,TeamIdentity!C:C,NONE)} -> 00010001 | F3: {=_xlfn.XLOOKUP(_xlfn.XLOOKUP(G3,New!A:A,New!F:F,NONE),TeamIdentity!A:A,TeamIdentity!C:C,NONE)} -> 00001100 | G3: =_xlfn.CONCAT(AU3,"-",AV3) -> 0-10 | H3: 00000000000000000000000000000000 | I3: 00000000000000000000000000000000 | J3: 00000000000000000000000000000000 | K3: 00101101010010100000000000000011 | L3: 00000000000000000000000000000000 | M3: 00000000000000000000000000000000 | N3: 00000000000000000000000000000000 | O3: 00000000000000000000000000000000 | P3: 00000000000000000000000000000000 | Q3: 00000000000000000000000000000000 | R3: 00101101010010100000000000001110 | S3: 90319 | T3: 0 | U3: 90318 | V3: 0 | W3: Unplayed | X3: 0 | Y3: 0 | Z3: 1200 | AA3: Pending | AB3: 0 | AC3: 0 | AD3: 0 | AE3: 0 | AF3: Regular | AG3: 0 | AH3: 0 | AI3: 0 | AJ3: 0 | AK3: Saturday | AL3: 0 | AM3: 0 | AN3: 0 | AO3: 0 | AP3: FALSE | AQ3: Invalid_ | AR3: Invalid_ | AS3: PreSeason | AT3: 14 | AU3: 0 | AV3: 10 | AW3: 11 | AX3: FALSE | AY3: FALSE | AZ3: FALSE | BA3: FALSE | BB3: FALSE | BC3: FALSE | BD3: FALSE | BE3: IsDefenseOnly | BF3: Pending | BG3: None | BH3: Invalid_ | BI3: Invalid_
A4: {=_xlfn.IFS(AS4="RegularSeason",C4,AS4<>"RegularSeason",R4)} -> 00101101010010100000000000100000 | B4: {=_xlfn.IFS(AS4="RegularSeason",D4,AS4<>"RegularSeason",K4)} -> 00101101010010100000000000000010 | C4: =_xlfn.CONCAT(LEFT(R4,24),E4) -> 00101101010010100000000000001110 | D4: =_xlfn.CONCAT(LEFT(K4,24),F4) -> 00101101010010100000000000010011 | E4: {=_xlfn.XLOOKUP(_xlfn.XLOOKUP(G4,New!A:A,New!M:M,NONE),TeamIdentity!A:A,TeamIdentity!C:C,NONE)} -> 00001110 | F4: {=_xlfn.XLOOKUP(_xlfn.XLOOKUP(G4,New!A:A,New!F:F,NONE),TeamIdentity!A:A,TeamIdentity!C:C,NONE)} -> 00010011 | G4: =_xlfn.CONCAT(AU4,"-",AV4) -> 0-15 | H4: 00000000000000000000000000000000 | I4: 00000000000000000000000000000000 | J4: 00000000000000000000000000000000 | K4: 00101101010010100000000000000010 | L4: 00000000000000000000000000000000 | M4: 00000000000000000000000000000000 | N4: 00000000000000000000000000000000 | O4: 00000000000000000000000000000000 | P4: 00000000000000000000000000000000 | Q4: 00000000000000000000000000000000 | R4: 00101101010010100000000000100000 | S4: 90325 | T4: 0 | U4: 90324 | V4: 0 | W4: Unplayed | X4: 0 | Y4: 0 | Z4: 1380 | AA4: Pending | AB4: 0 | AC4: 0 | AD4: 0 | AE4: 0 | AF4: Regular | AG4: 0 | AH4: 0 | AI4: 0 | AJ4: 0 | AK4: Saturday | AL4: 0 | AM4: 0 | AN4: 0 | AO4: 0 | AP4: FALSE | AQ4: Invalid_ | AR4: Invalid_ | AS4: PreSeason | AT4: 14 | AU4: 0 | AV4: 15 | AW4: 11 | AX4: FALSE | AY4: FALSE | AZ4: FALSE | BA4: FALSE | BB4: FALSE | BC4: FALSE | BD4: FALSE | BE4: IsDefenseOnly | BF4: Pending | BG4: None | BH4: Invalid_ | BI4: Invalid_
A5: {=_xlfn.IFS(AS5="RegularSeason",C5,AS5<>"RegularSeason",R5)} -> 00101101010010100000000000010001 | B5: {=_xlfn.IFS(AS5="RegularSeason",D5,AS5<>"RegularSeason",K5)} -> 00101101010010100000000000000101 | C5: =_xlfn.CONCAT(LEFT(R5,24),E5) -> 00101101010010100000000000011111 | D5: =_xlfn.CONCAT(LEFT(K5,24),F5) -> 00101101010010100000000000000110 | E5: {=_xlfn.XLOOKUP(_xlfn.XLOOKUP(G5,New!A:A,New!M:M,NONE),TeamIdentity!A:A,TeamIdentity!C:C,NONE)} -> 00011111 | F5: {=_xlfn.XLOOKUP(_xlfn.XLOOKUP(G5,New!A:A,New!F:F,NONE),TeamIdentity!A:A,TeamIdentity!C:C,NONE)} -> 00000110 | G5: =_xlfn.CONCAT(AU5,"-",AV5) -> 0-2 | H5: 00000000000000000000000000000000 | I5: 00000000000000000000000000000000 | J5: 00000000000000000000000000000000 | K5: 00101101010010100000000000000101 | L5: 00000000000000000000000000000000 | M5: 00000000000000000000000000000000 | N5: 00000000000000000000000000000000 | O5: 00000000000000000000000000000000 | P5: 00000000000000000000000000000000 | Q5: 00000000000000000000000000000000 | R5: 00101101010010100000000000010001 | S5: 90301 | T5: 0 | U5: 90300 | V5: 0 | W5: Unplayed | X5: 0 | Y5: 0 | Z5: 1140 | AA5: Pending | AB5: 0 | AC5: 0 | AD5: 0 | AE5: 0 | AF5: Regular | AG5: 0 | AH5: 0 | AI5: 0 | AJ5: 0 | AK5: Friday | AL5: 0 | AM5: 0 | AN5: 0 | AO5: 0 | AP5: FALSE | AQ5: Invalid_ | AR5: Invalid_ | AS5: PreSeason | AT5: 14 | AU5: 0 | AV5: 2 | AW5: 11 | AX5: FALSE | AY5: FALSE | AZ5: FALSE | BA5: FALSE | BB5: FALSE | BC5: FALSE | BD5: FALSE | BE5: IsDefenseOnly | BF5: Pending | BG5: None | BH5: Invalid_ | BI5: Invalid_
A6: {=_xlfn.IFS(AS6="RegularSeason",C6,AS6<>"RegularSeason",R6)} -> 00101101010010100000000000011010 | B6: {=_xlfn.IFS(AS6="RegularSeason",D6,AS6<>"RegularSeason",K6)} -> 00101101010010100000000000010110 | C6: =_xlfn.CONCAT(LEFT(R6,24),E6) -> 00101101010010100000000000011101 | D6: =_xlfn.CONCAT(LEFT(K6,24),F6) -> 00101101010010100000000000000101 | E6: {=_xlfn.XLOOKUP(_xlfn.XLOOKUP(G6,New!A:A,New!M:M,NONE),TeamIdentity!A:A,TeamIdentity!C:C,NONE)} -> 00011101 | F6: {=_xlfn.XLOOKUP(_xlfn.XLOOKUP(G6,New!A:A,New!F:F,NONE),TeamIdentity!A:A,TeamIdentity!C:C,NONE)} -> 00000101 | G6: =_xlfn.CONCAT(AU6,"-",AV6) -> 0-11 | H6: 00000000000000000000000000000000 | I6: 00000000000000000000000000000000 | J6: 00000000000000000000000000000000 | K6: 00101101010010100000000000010110 | L6: 00000000000000000000000000000000 | M6: 00000000000000000000000000000000 | N6: 00000000000000000000000000000000 | O6: 00000000000000000000000000000000 | P6: 00000000000000000000000000000000 | Q6: 00000000000000000000000000000000 | R6: 00101101010010100000000000011010 | S6: 90315 | T6: 0 | U6: 90314 | V6: 0 | W6: Unplayed | X6: 0 | Y6: 0 | Z6: 1200 | AA6: Pending | AB6: 0 | AC6: 0 | AD6: 0 | AE6: 0 | AF6: Regular | AG6: 0 | AH6: 0 | AI6: 0 | AJ6: 0 | AK6: Saturday | AL6: 0 | AM6: 0 | AN6: 0 | AO6: 0 | AP6: FALSE | AQ6: Invalid_ | AR6: Invalid_ | AS6: PreSeason | AT6: 14 | AU6: 0 | AV6: 11 | AW6: 11 | AX6: FALSE | AY6: FALSE | AZ6: FALSE | BA6: FALSE | BB6: FALSE | BC6: FALSE | BD6: FALSE | BE6: IsDefenseOnly | BF6: Pending | BG6: None | BH6: Invalid_ | BI6: Invalid_
A7: {=_xlfn.IFS(AS7="RegularSeason",C7,AS7<>"RegularSeason",R7)} -> 00101101010010100000000000010101 | B7: {=_xlfn.IFS(AS7="RegularSeason",D7,AS7<>"RegularSeason",K7)} -> 00101101010010100000000000001101 | C7: =_xlfn.CONCAT(LEFT(R7,24),E7) -> 00101101010010100000000000000011 | D7: =_xlfn.CONCAT(LEFT(K7,24),F7) -> 00101101010010100000000000011011 | E7: {=_xlfn.XLOOKUP(_xlfn.XLOOKUP(G7,New!A:A,New!M:M,NONE),TeamIdentity!A:A,TeamIdentity!C:C,NONE)} -> 00000011 | F7: {=_xlfn.XLOOKUP(_xlfn.XLOOKUP(G7,New!A:A,New!F:F,NONE),TeamIdentity!A:A,TeamIdentity!C:C,NONE)} -> 00011011 | G7: =_xlfn.CONCAT(AU7,"-",AV7) -> 0-12 | H7: 00000000000000000000000000000000 | I7: 00000000000000000000000000000000 | J7: 00000000000000000000000000000000 | K7: 00101101010010100000000000001101 | L7: 00000000000000000000000000000000 | M7: 00000000000000000000000000000000 | N7: 00000000000000000000000000000000 | O7: 00000000000000000000000000000000 | P7: 00000000000000000000000000000000 | Q7: 00000000000000000000000000000000 | R7: 00101101010010100000000000010101 | S7: 90317 | T7: 0 | U7: 90316 | V7: 0 | W7: Unplayed | X7: 0 | Y7: 0 | Z7: 1200 | AA7: Pending | AB7: 0 | AC7: 0 | AD7: 0 | AE7: 0 | AF7: Regular | AG7: 0 | AH7: 0 | AI7: 0 | AJ7: 0 | AK7: Saturday | AL7: 0 | AM7: 0 | AN7: 0 | AO7: 0 | AP7: FALSE | AQ7: Invalid_ | AR7: Invalid_ | AS7: PreSeason | AT7: 14 | AU7: 0 | AV7: 12 | AW7: 11 | AX7: FALSE | AY7: FALSE | AZ7: FALSE | BA7: FALSE | BB7: FALSE | BC7: FALSE | BD7: FALSE | BE7: IsDefenseOnly | BF7: Pending | BG7: None | BH7: Invalid_ | BI7: Invalid_
A8: {=_xlfn.IFS(AS8="RegularSeason",C8,AS8<>"RegularSeason",R8)} -> 00101101010010100000000000001111 | B8: {=_xlfn.IFS(AS8="RegularSeason",D8,AS8<>"RegularSeason",K8)} -> 00101101010010100000000000000000 | C8: =_xlfn.CONCAT(LEFT(R8,24),E8) -> 00101101010010100000000000001010 | D8: =_xlfn.CONCAT(LEFT(K8,24),F8) -> 00101101010010100000000000010111 | E8: {=_xlfn.XLOOKUP(_xlfn.XLOOKUP(G8,New!A:A,New!M:M,NONE),TeamIdentity!A:A,TeamIdentity!C:C,NONE)} -> 00001010 | F8: {=_xlfn.XLOOKUP(_xlfn.XLOOKUP(G8,New!A:A,New!F:F,NONE),TeamIdentity!A:A,TeamIdentity!C:C,NONE)} -> 00010111 | G8: =_xlfn.CONCAT(AU8,"-",AV8) -> 0-3 | H8: 00000000000000000000000000000000 | I8: 00000000000000000000000000000000 | J8: 00000000000000000000000000000000 | K8: 00101101010010100000000000000000 | L8: 00000000000000000000000000000000 | M8: 00000000000000000000000000000000 | N8: 00000000000000000000000000000000 | O8: 00000000000000000000000000000000 | P8: 00000000000000000000000000000000 | Q8: 00000000000000000000000000000000 | R8: 00101101010010100000000000001111 | S8: 90299 | T8: 0 | U8: 90298 | V8: 0 | W8: Unplayed | X8: 0 | Y8: 0 | Z8: 1140 | AA8: Pending | AB8: 0 | AC8: 0 | AD8: 0 | AE8: 0 | AF8: Regular | AG8: 0 | AH8: 0 | AI8: 0 | AJ8: 0 | AK8: Friday | AL8: 0 | AM8: 0 | AN8: 0 | AO8: 0 | AP8: FALSE | AQ8: Invalid_ | AR8: Invalid_ | AS8: PreSeason | AT8: 14 | AU8: 0 | AV8: 3 | AW8: 11 | AX8: FALSE | AY8: FALSE | AZ8: FALSE | BA8: FALSE | BB8: FALSE | BC8: FALSE | BD8: FALSE | BE8: IsDefenseOnly | BF8: Pending | BG8: None | BH8: Invalid_ | BI8: Invalid_
A9: {=_xlfn.IFS(AS9="RegularSeason",C9,AS9<>"RegularSeason",R9)} -> 00101101010010100000000000010111 | B9: {=_xlfn.IFS(AS9="RegularSeason",D9,AS9<>"RegularSeason",K9)} -> 00101101010010100000000000010101 | C9: =_xlfn.CONCAT(LEFT(R9,24),E9) -> 00101101010010100000000000000110 | D9: =_xlfn.CONCAT(LEFT(K9,24),F9) -> 00101101010010100000000000010101 | E9: {=_xlfn.XLOOKUP(_xlfn.XLOOKUP(G9,New!A:A,New!M:M,NONE),TeamIdentity!A:A,TeamIdentity!C:C,NONE)} -> 00000110 | F9: {=_xlfn.XLOOKUP(_xlfn.XLOOKUP(G9,New!A:A,New!F:F,NONE),TeamIdentity!A:A,TeamIdentity!C:C,NONE)} -> 00010101 | G9: =_xlfn.CONCAT(AU9,"-",AV9) -> 1-9 | H9: 00000000000000000000000000000000 | I9: 00000000000000000000000000000000 | J9: 00000000000000000000000000000000 | K9: 00101101010010100000000000010101 | L9: 00000000000000000000000000000000 | M9: 00000000000000000000000000000000 | N9: 00000000000000000000000000000000 | O9: 00000000000000000000000000000000 | P9: 00000000000000000000000000000000 | Q9: 00000000000000000000000000000000 | R9: 00101101010010100000000000010111 | S9: -1 | T9: 0 | U9: -1 | V9: 0 | W9: Unplayed | X9: 0 | Y9: 0 | Z9: 1200 | AA9: Pending | AB9: 0 | AC9: 0 | AD9: 0 | AE9: 0 | AF9: Regular | AG9: 0 | AH9: 0 | AI9: 0 | AJ9: 0 | AK9: Friday | AL9: 0 | AM9: 0 | AN9: 0 | AO9: 0 | AP9: FALSE | AQ9: Invalid_ | AR9: Invalid_ | AS9: PreSeason | AT9: 14 | AU9: 1 | AV9: 9 | AW9: 11 | AX9: FALSE | AY9: FALSE | AZ9: FALSE | BA9: FALSE | BB9: FALSE | BC9: FALSE | BD9: FALSE | BE9: IsDefenseOnly | BF9: Pending | BG9: None | BH9: Invalid_ | BI9: Invalid_
A10: {=_xlfn.IFS(AS10="RegularSeason",C10,AS10<>"RegularSeason",R10)} -> 00101101010010100000000000010000 | B10: {=_xlfn.IFS(AS10="RegularSeason",D10,AS10<>"RegularSeason",K10)} -> 00101101010010100000000000011110 | C10: =_xlfn.CONCAT(LEFT(R10,24),E10) -> 00101101010010100000000000000000 | D10: =_xlfn.CONCAT(LEFT(K10,24),F10) -> 00101101010010100000000000100000 | E10: {=_xlfn.XLOOKUP(_xlfn.XLOOKUP(G10,New!A:A,New!M:M,NONE),TeamIdentity!A:A,TeamIdentity!C:C,NONE)} -> 00000000 | F10: {=_xlfn.XLOOKUP(_xlfn.XLOOKUP(G10,New!A:A,New!F:F,NONE),TeamIdentity!A:A,TeamIdentity!C:C,NONE)} -> 00100000 | G10: =_xlfn.CONCAT(AU10,"-",AV10) -> 0-7 | H10: 00000000000000000000000000000000 | I10: 00000000000000000000000000000000 | J10: 00000000000000000000000000000000 | K10: 00101101010010100000000000011110 | L10: 00000000000000000000000000000000 | M10: 00000000000000000000000000000000 | N10: 00000000000000000000000000000000 | O10: 00000000000000000000000000000000 | P10: 00000000000000000000000000000000 | Q10: 00000000000000000000000000000000 | R10: 00101101010010100000000000010000 | S10: 90309 | T10: 0 | U10: 90308 | V10: 0 | W10: Unplayed | X10: 0 | Y10: 0 | Z10: 1140 | AA10: Pending | AB10: 0 | AC10: 0 | AD10: 0 | AE10: 0 | AF10: Regular | AG10: 0 | AH10: 0 | AI10: 0 | AJ10: 0 | AK10: Saturday | AL10: 0 | AM10: 0 | AN10: 0 | AO10: 0 | AP10: FALSE | AQ10: Invalid_ | AR10: Invalid_ | AS10: PreSeason | AT10: 14 | AU10: 0 | AV10: 7 | AW10: 11 | AX10: FALSE | AY10: FALSE | AZ10: FALSE | BA10: FALSE | BB10: FALSE | BC10: FALSE | BD10: FALSE | BE10: IsDefenseOnly | BF10: Pending | BG10: None | BH10: Invalid_ | BI10: Invalid_
A11: {=_xlfn.IFS(AS11="RegularSeason",C11,AS11<>"RegularSeason",R11)} -> 00101101010010100000000000000111 | B11: {=_xlfn.IFS(AS11="RegularSeason",D11,AS11<>"RegularSeason",K11)} -> 00101101010010100000000000001100 | C11: =_xlfn.CONCAT(LEFT(R11,24),E11) -> 00101101010010100000000000011110 | D11: =_xlfn.CONCAT(LEFT(K11,24),F11) -> 00101101010010100000000000000010 | E11: {=_xlfn.XLOOKUP(_xlfn.XLOOKUP(G11,New!A:A,New!M:M,NONE),TeamIdentity!A:A,TeamIdentity!C:C,NONE)} -> 00011110 | F11: {=_xlfn.XLOOKUP(_xlfn.XLOOKUP(G11,New!A:A,New!F:F,NONE),TeamIdentity!A:A,TeamIdentity!C:C,NONE)} -> 00000010 | G11: =_xlfn.CONCAT(AU11,"-",AV11) -> 0-5 | H11: 00000000000000000000000000000000 | I11: 00000000000000000000000000000000 | J11: 00000000000000000000000000000000 | K11: 00101101010010100000000000001100 | L11: 00000000000000000000000000000000 | M11: 00000000000000000000000000000000 | N11: 00000000000000000000000000000000 | O11: 00000000000000000000000000000000 | P11: 00000000000000000000000000000000 | Q11: 00000000000000000000000000000000 | R11: 00101101010010100000000000000111 | S11: 90307 | T11: 0 | U11: 90306 | V11: 0 | W11: Unplayed | X11: 0 | Y11: 0 | Z11: 1320 | AA11: Pending | AB11: 0 | AC11: 0 | AD11: 0 | AE11: 0 | AF11: Regular | AG11: 0 | AH11: 0 | AI11: 0 | AJ11: 0 | AK11: Friday | AL11: 0 | AM11: 0 | AN11: 0 | AO11: 0 | AP11: FALSE | AQ11: Invalid_ | AR11: Invalid_ | AS11: PreSeason | AT11: 14 | AU11: 0 | AV11: 5 | AW11: 11 | AX11: FALSE | AY11: FALSE | AZ11: FALSE | BA11: FALSE | BB11: FALSE | BC11: FALSE | BD11: FALSE | BE11: IsDefenseOnly | BF11: Pending | BG11: None | BH11: Invalid_ | BI11: Invalid_
A12: {=_xlfn.IFS(AS12="RegularSeason",C12,AS12<>"RegularSeason",R12)} -> 00101101010010100000000000011011 | B12: {=_xlfn.IFS(AS12="RegularSeason",D12,AS12<>"RegularSeason",K12)} -> 00101101010010100000000000011001 | C12: =_xlfn.CONCAT(LEFT(R12,24),E12) -> 00101101010010100000000000010000 | D12: =_xlfn.CONCAT(LEFT(K12,24),F12) -> 00101101010010100000000000001111 | E12: {=_xlfn.XLOOKUP(_xlfn.XLOOKUP(G12,New!A:A,New!M:M,NONE),TeamIdentity!A:A,TeamIdentity!C:C,NONE)} -> 00010000 | F12: {=_xlfn.XLOOKUP(_xlfn.XLOOKUP(G12,New!A:A,New!F:F,NONE),TeamIdentity!A:A,TeamIdentity!C:C,NONE)} -> 00001111 | G12: =_xlfn.CONCAT(AU12,"-",AV12) -> 0-4 | H12: 00000000000000000000000000000000 | I12: 00000000000000000000000000000000 | J12: 00000000000000000000000000000000 | K12: 00101101010010100000000000011001 | L12: 00000000000000000000000000000000 | M12: 00000000000000000000000000000000 | N12: 00000000000000000000000000000000 | O12: 00000000000000000000000000000000 | P12: 00000000000000000000000000000000 | Q12: 00000000000000000000000000000000 | R12: 00101101010010100000000000011011 | S12: 90303 | T12: 0 | U12: 90302 | V12: 0 | W12: Unplayed | X12: 0 | Y12: 0 | Z12: 1200 | AA12: Pending | AB12: 0 | AC12: 0 | AD12: 0 | AE12: 0 | AF12: Regular | AG12: 0 | AH12: 0 | AI12: 0 | AJ12: 0 | AK12: Friday | AL12: 0 | AM12: 0 | AN12: 0 | AO12: 0 | AP12: FALSE | AQ12: Invalid_ | AR12: Invalid_ | AS12: PreSeason | AT12: 14 | AU12: 0 | AV12: 4 | AW12: 11 | AX12: FALSE | AY12: FALSE | AZ12: FALSE | BA12: FALSE | BB12: FALSE | BC12: FALSE | BD12: FALSE | BE12: IsDefenseOnly | BF12: Pending | BG12: None | BH12: Invalid_ | BI12: Invalid_
A13: {=_xlfn.IFS(AS13="RegularSeason",C13,AS13<>"RegularSeason",R13)} -> 00101101010010100000000000100001 | B13: {=_xlfn.IFS(AS13="RegularSeason",D13,AS13<>"RegularSeason",K13)} -> 00101101010010100000000000010011 | C13: =_xlfn.CONCAT(LEFT(R13,24),E13) -> 00101101010010100000000000100011 | D13: =_xlfn.CONCAT(LEFT(K13,24),F13) -> 00101101010010100000000000100001 | E13: {=_xlfn.XLOOKUP(_xlfn.XLOOKUP(G13,New!A:A,New!M:M,NONE),TeamIdentity!A:A,TeamIdentity!C:C,NONE)} -> 00100011 | F13: {=_xlfn.XLOOKUP(_xlfn.XLOOKUP(G13,New!A:A,New!F:F,NONE),TeamIdentity!A:A,TeamIdentity!C:C,NONE)} -> 00100001 | G13: =_xlfn.CONCAT(AU13,"-",AV13) -> 0-8 | H13: 00000000000000000000000000000000 | I13: 00000000000000000000000000000000 | J13: 00000000000000000000000000000000 | K13: 00101101010010100000000000010011 | L13: 00000000000000000000000000000000 | M13: 00000000000000000000000000000000 | N13: 00000000000000000000000000000000 | O13: 00000000000000000000000000000000 | P13: 00000000000000000000000000000000 | Q13: 00000000000000000000000000000000 | R13: 00101101010010100000000000100001 | S13: 90311 | T13: 0 | U13: 90310 | V13: 0 | W13: Unplayed | X13: 0 | Y13: 0 | Z13: 1140 | AA13: Pending | AB13: 0 | AC13: 0 | AD13: 0 | AE13: 0 | AF13: Regular | AG13: 0 | AH13: 0 | AI13: 0 | AJ13: 0 | AK13: Saturday | AL13: 0 | AM13: 0 | AN13: 0 | AO13: 0 | AP13: FALSE | AQ13: Invalid_ | AR13: Invalid_ | AS13: PreSeason | AT13: 14 | AU13: 0 | AV13: 8 | AW13: 11 | AX13: FALSE | AY13: FALSE | AZ13: FALSE | BA13: FALSE | BB13: FALSE | BC13: FALSE | BD13: FALSE | BE13: IsDefenseOnly | BF13: Pending | BG13: None | BH13: Invalid_ | BI13: Invalid_
... A430: {=_xlfn.IFS(AS430="RegularSeason",C430,AS430<>"RegularSeason",R430)} -> 00000000000000000000000000000000 | B430: {=_xlfn.IFS(AS430="RegularSeason",D430,AS430<>"RegularSeason",K430)} -> 00000000000000000000000000000000 | C430: =_xlfn.CONCAT(LEFT(R430,24),E430) -> 00000000000000000000000000011001 | D430: =_xlfn.CONCAT(LEFT(K430,24),F430) -> 00000000000000000000000000100100 | E430: {=_xlfn.XLOOKUP(_xlfn.XLOOKUP(G430,New!A:A,New!M:M,NONE),TeamIdentity!A:A,TeamIdentity!C:C,NONE)} -> 00011001 | F430: {=_xlfn.XLOOKUP(_xlfn.XLOOKUP(G430,New!A:A,New!F:F,NONE),TeamIdentity!A:A,TeamIdentity!C:C,NONE)} -> 00100100 | G430: =_xlfn.CONCAT(AU430,"-",AV430) -> 0-0 | H430: 00000000000000000000000110101101 | I430: 00000000000000000000000000000000 | J430: 00000000000000000000000000000000 | K430: 00000000000000000000000000000000 | L430: 00000000000000000000000000000000 | M430: 00000000000000000000000000000000 | N430: 00000000000000000000000000000000 | O430: 00000000000000000000000000000000 | P430: 00000000000000000000000000000000 | Q430: 00000000000000000000000000000000 | R430: 00000000000000000000000000000000 | S430: -2147483648 | T430: -2147483648 | U430: -2147483648 | V430: 0 | W430: Unscheduled | X430: 0 | Y430: 0 | Z430: 0 | AA430: Pending | AB430: 0 | AC430: 0 | AD430: 0 | AE430: -100 | AF430: Regular | AG430: 0 | AH430: 0 | AI430: 0 | AJ430: 0 | AK430: Sunday | AL430: 0 | AM430: 0 | AN430: 0 | AO430: 0 | AP430: FALSE | AQ430: None | AR430: Clear | AS430: PreSeason | AT430: 0 | AU430: 0 | AV430: 0 | AW430: 0 | AX430: FALSE | AY430: FALSE | AZ430: FALSE | BA430: FALSE | BB430: FALSE | BC430: FALSE | BD430: FALSE | BE430: IsPlayTheMoment | BF430: Pending | BG430: Home | BH430: Calm | BI430: None

Sheet New
A1: Concat | B1: GameID | C1: AwayPlayerStatCache | D1: Stadium | E1: ScoringSummaries | F1: AwayTeam | G1: AwayTeamStatCache | H1: GameGoal | I1: GameSetup | J1: HomePlayerStatCache | K1: InjuryCache | L1: HomeTeamStatCache | M1: HomeTeam | N1: AwayRequestId | O1: GameSessionId | P1: HomeRequestId | Q1: InitialMomentum | R1: GameStatus | S1: AwayScore | T1: NumberTimesPlayed | U1: TimeOfDay | V1: HomeTeamStatus | W1: AwayScoreQuarter1 | X1: AwayScoreOT | Y1: HomeScore | Z1: Temperature | AA1: LiveSeasonGameType | AB1: HomeScoreOT | AC1: AwayScoreQuarter4 | AD1: AwayScoreQuarter3 | AE1: AwayScoreQuarter2 | AF1: DayOfWeek | AG1: HomeScoreQuarter4 | AH1: HomeScoreQuarter3 | AI1: HomeScoreQuarter2 | AJ1: HomeScoreQuarter1 | AK1: IsGameOfTheWeek | AL1: CloudCover | AM1: Weather | AN1: SeasonWeekType | AO1: QuarterLengthMins | AP1: SeasonWeek | AQ1: SeasonGameNum | AR1: SeasonYear | AS1: ThanksgivingFlag | AT1: ChristmasFlag | AU1: NewYearsFlag | AV1: IsSimmed | AW1: HasBeenPublished | AX1: IsPractice | AY1: IsOvertimeGame | AZ1: PlayMomentType | BA1: AwayTeamStatus | BB1: ForceWin | BC1: Wind | BD1: Precipitation | BE1: NewSeasonWeek
A2: 0-0 | B2: 185 | C2: 0 | D2: 0 | E2: 0 | F2: Vikings | G2: 0 | H2: 0 | I2: 0 | J2: 0 | K2: 0 | L2: 0 | M2: Packers | N2: -1 | O2: 0 | P2: -1 | Q2: 0 | R2: Unplayed | S2: 0 | T2: 0 | U2: 1220 | V2: Pending | W2: 0 | X2: 0 | Y2: 0 | Z2: 0 | AA2: Thursday | AB2: 0 | AC2: 0 | AD2: 0 | AE2: 0 | AF2: Thursday | AG2: 0 | AH2: 0 | AI2: 0 | AJ2: 0 | AK2: FALSE | AL2: Invalid_ | AM2: Invalid_ | AN2: RegularSeason | AO2: 14 | AP2: 2 | AQ2: 15 | AR2: 11 | AS2: FALSE | AT2: FALSE | AU2: FALSE | AV2: FALSE | AW2: FALSE | AX2: FALSE | AY2: FALSE | AZ2: IsDefenseOnly | BA2: Pending | BC2: Invalid_ | BD2: Invalid_ | BE2: 0
A3: 0-1 | B3: 321 | C3: 0 | D3: 0 | E3: 0 | F3: Commanders | G3: 0 | H3: 0 | I3: 0 | J3: 0 | K3: 0 | L3: 0 | M3: Cardinals | N3: -1 | O3: 0 | P3: -1 | Q3: 0 | R3: Unplayed | S3: 0 | T3: 0 | U3: 965 | V3: Pending | W3: 0 | X3: 0 | Y3: 0 | Z3: 0 | AA3: Regular | AB3: 0 | AC3: 0 | AD3: 0 | AE3: 0 | AF3: Sunday | AG3: 0 | AH3: 0 | AI3: 0 | AJ3: 0 | AK3: FALSE | AL3: Invalid_ | AM3: Invalid_ | AN3: RegularSeason | AO3: 14 | AP3: 2 | AQ3: 11 | AR3: 11 | AS3: FALSE | AT3: FALSE | AU3: FALSE | AV3: FALSE | AW3: FALSE | AX3: FALSE | AY3: FALSE | AZ3: IsDefenseOnly | BA3: Pending | BC3: Invalid_ | BD3: Invalid_ | BE3: 0
A4: 0-2 | B4: 164 | C4: 0 | D4: 0 | E4: 0 | F4: Buccaneers | G4: 0 | H4: 0 | I4: 0 | J4: 0 | K4: 0 | L4: 0 | M4: Saints | N4: -1 | O4: 0 | P4: -1 | Q4: 0 | R4: Unplayed | S4: 0 | T4: 0 | U4: 780 | V4: Pending | W4: 0 | X4: 0 | Y4: 0 | Z4: 0 | AA4: Regular | AB4: 0 | AC4: 0 | AD4: 0 | AE4: 0 | AF4: Sunday | AG4: 0 | AH4: 0 | AI4: 0 | AJ4: 0 | AK4: FALSE | AL4: Invalid_ | AM4: Invalid_ | AN4: RegularSeason | AO4: 14 | AP4: 3 | AQ4: 4 | AR4: 11 | AS4: FALSE | AT4: FALSE | AU4: FALSE | AV4: FALSE | AW4: FALSE | AX4: FALSE | AY4: FALSE | AZ4: IsDefenseOnly | BA4: Pending | BC4: Invalid_ | BD4: Invalid_ | BE4: 0
A5: 0-3 | B5: 294 | C5: 0 | D5: 0 | E5: 0 | F5: Lions | G5: 0 | H5: 0 | I5: 0 | J5: 0 | K5: 0 | L5: 0 | M5: Chargers | N5: -1 | O5: 0 | P5: -1 | Q5: 0 | R5: Unplayed | S5: 0 | T5: 0 | U5: 965 | V5: Pending | W5: 0 | X5: 0 | Y5: 0 | Z5: 0 | AA5: Regular | AB5: 0 | AC5: 0 | AD5: 0 | AE5: 0 | AF5: Sunday | AG5: 0 | AH5: 0 | AI5: 0 | AJ5: 0 | AK5: FALSE | AL5: Invalid_ | AM5: Invalid_ | AN5: RegularSeason | AO5: 14 | AP5: 2 | AQ5: 12 | AR5: 11 | AS5: FALSE | AT5: FALSE | AU5: FALSE | AV5: FALSE | AW5: FALSE | AX5: FALSE | AY5: FALSE | AZ5: IsDefenseOnly | BA5: Pending | BC5: Invalid_ | BD5: Invalid_ | BE5: 0
A6: 0-4 | B6: 263 | C6: 0 | D6: 0 | E6: 0 | F6: Dolphins | G6: 0 | H6: 0 | I6: 0 | J6: 0 | K6: 0 | L6: 0 | M6: Eagles | N6: -1 | O6: 0 | P6: -1 | Q6: 0 | R6: Unplayed | S6: 0 | T6: 0 | U6: 1220 | V6: Pending | W6: 0 | X6: 0 | Y6: 0 | Z6: 0 | AA6: Sunday | AB6: 0 | AC6: 0 | AD6: 0 | AE6: 0 | AF6: Sunday | AG6: 0 | AH6: 0 | AI6: 0 | AJ6: 0 | AK6: FALSE | AL6: Invalid_ | AM6: Invalid_ | AN6: RegularSeason | AO6: 14 | AP6: 5 | AQ6: 11 | AR6: 11 | AS6: FALSE | AT6: FALSE | AU6: FALSE | AV6: FALSE | AW6: FALSE | AX6: FALSE | AY6: FALSE | AZ6: IsDefenseOnly | BA6: Pending | BC6: Invalid_ | BD6: Invalid_ | BE6: 0
A7: 0-5 | B7: 300 | C7: 0 | D7: 0 | E7: 0 | F7: Bengals | G7: 0 | H7: 0 | I7: 0 | J7: 0 | K7: 0 | L7: 0 | M7: Ravens | N7: -1 | O7: 0 | P7: -1 | Q7: 0 | R7: Unplayed | S7: 0 | T7: 0 | U7: 780 | V7: Pending | W7: 0 | X7: 0 | Y7: 0 | Z7: 0 | AA7: Regular | AB7: 0 | AC7: 0 | AD7: 0 | AE7: 0 | AF7: Sunday | AG7: 0 | AH7: 0 | AI7: 0 | AJ7: 0 | AK7: FALSE | AL7: Invalid_ | AM7: Invalid_ | AN7: RegularSeason | AO7: 14 | AP7: 5 | AQ7: 5 | AR7: 11 | AS7: FALSE | AT7: FALSE | AU7: FALSE | AV7: FALSE | AW7: FALSE | AX7: FALSE | AY7: FALSE | AZ7: IsDefenseOnly | BA7: Pending | BC7: Invalid_ | BD7: Invalid_ | BE7: 0
A8: 0-6 | B8: 67 | C8: 0 | D8: 0 | E8: 0 | F8: Jaguars | G8: 0 | H8: 0 | I8: 0 | J8: 0 | K8: 0 | L8: 0 | M8: Texans | N8: -1 | O8: 0 | P8: -1 | Q8: 0 | R8: Unplayed | S8: 0 | T8: 0 | U8: 780 | V8: Pending | W8: 0 | X8: 0 | Y8: 0 | Z8: 0 | AA8: Regular | AB8: 0 | AC8: 0 | AD8: 0 | AE8: 0 | AF8: Sunday | AG8: 0 | AH8: 0 | AI8: 0 | AJ8: 0 | AK8: FALSE | AL8: Invalid_ | AM8: Invalid_ | AN8: RegularSeason | AO8: 14 | AP8: 6 | AQ8: 2 | AR8: 11 | AS8: FALSE | AT8: FALSE | AU8: FALSE | AV8: FALSE | AW8: FALSE | AX8: FALSE | AY8: FALSE | AZ8: IsDefenseOnly | BA8: Pending | BC8: Invalid_ | BD8: Invalid_ | BE8: 0
A9: 0-7 | B9: 273 | C9: 0 | D9: 0 | E9: 0 | F9: Seahawks | G9: 0 | H9: 0 | I9: 0 | J9: 0 | K9: 0 | L9: 0 | M9: 49ers | N9: -1 | O9: 0 | P9: -1 | Q9: 0 | R9: Unplayed | S9: 0 | T9: 0 | U9: 965 | V9: Pending | W9: 0 | X9: 0 | Y9: 0 | Z9: 0 | AA9: Regular | AB9: 0 | AC9: 0 | AD9: 0 | AE9: 0 | AF9: Sunday | AG9: 0 | AH9: 0 | AI9: 0 | AJ9: 0 | AK9: FALSE | AL9: Invalid_ | AM9: Invalid_ | AN9: RegularSeason | AO9: 14 | AP9: 6 | AQ9: 7 | AR9: 11 | AS9: FALSE | AT9: FALSE | AU9: FALSE | AV9: FALSE | AW9: FALSE | AX9: FALSE | AY9: FALSE | AZ9: IsDefenseOnly | BA9: Pending | BC9: Invalid_ | BD9: Invalid_ | BE9: 0
A10: 0-8 | B10: 230 | C10: 0 | D10: 0 | E10: 0 | F10: Steelers | G10: 0 | H10: 0 | I10: 0 | J10: 0 | K10: 0 | L10: 0 | M10: Titans | N10: -1 | O10: 0 | P10: -1 | Q10: 0 | R10: Unplayed | S10: 0 | T10: 0 | U10: 780 | V10: Pending | W10: 0 | X10: 0 | Y10: 0 | Z10: 0 | AA10: Regular | AB10: 0 | AC10: 0 | AD10: 0 | AE10: 0 | AF10: Sunday | AG10: 0 | AH10: 0 | AI10: 0 | AJ10: 0 | AK10: FALSE | AL10: Invalid_ | AM10: Invalid_ | AN10: RegularSeason | AO10: 14 | AP10: 7 | AQ10: 6 | AR10: 11 | AS10: FALSE | AT10: FALSE | AU10: FALSE | AV10: FALSE | AW10: FALSE | AX10: FALSE | AY10: FALSE | AZ10: IsDefenseOnly | BA10: Pending | BC10: Invalid_ | BD10: Invalid_ | BE10: 0
A11: 0-9 | B11: 82 | C11: 0 | D11: 0 | E11: 0 | F11: Panthers | G11: 0 | H11: 0 | I11: 0 | J11: 0 | K11: 0 | L11: 0 | M11: Bears | N11: -1 | O11: 0 | P11: -1 | Q11: 0 | R11: Unplayed | S11: 0 | T11: 0 | U11: 780 | V11: Pending | W11: 0 | X11: 0 | Y11: 0 | Z11: 0 | AA11: Regular | AB11: 0 | AC11: 0 | AD11: 0 | AE11: 0 | AF11: Sunday | AG11: 0 | AH11: 0 | AI11: 0 | AJ11: 0 | AK11: FALSE | AL11: Invalid_ | AM11: Invalid_ | AN11: RegularSeason | AO11: 14 | AP11: 9 | AQ11: 5 | AR11: 11 | AS11: FALSE | AT11: FALSE | AU11: FALSE | AV11: FALSE | AW11: FALSE | AX11: FALSE | AY11: FALSE | AZ11: IsDefenseOnly | BA11: Pending | BC11: Invalid_ | BD11: Invalid_ | BE11: 0
A12: 0-10 | B12: 71 | C12: 0 | D12: 0 | E12: 0 | F12: Colts | G12: 0 | H12: 0 | I12: 0 | J12: 0 | K12: 0 | L12: 0 | M12: Falcons | N12: -1 | O12: 0 | P12: -1 | Q12: 0 | R12: Unplayed | S12: 0 | T12: 0 | U12: 1220 | V12: Pending | W12: 0 | X12: 0 | Y12: 0 | Z12: 0 | AA12: Thursday | AB12: 0 | AC12: 0 | AD12: 0 | AE12: 0 | AF12: Thursday | AG12: 0 | AH12: 0 | AI12: 0 | AJ12: 0 | AK12: FALSE | AL12: Invalid_ | AM12: Invalid_ | AN12: RegularSeason | AO12: 14 | AP12: 9 | AQ12: 13 | AR12: 11 | AS12: FALSE | AT12: FALSE | AU12: FALSE | AV12: FALSE | AW12: FALSE | AX12: FALSE | AY12: FALSE | AZ12: IsDefenseOnly | BA12: Pending | BC12: Invalid_ | BD12: Invalid_ | BE12: 0
